<?xml version="1.0"?>
<robot name="joyit" xmlns:xacro="http://www.ros.org/wiki/xacro">
    <xacro:include filename="$(find robot_manipulator_5dof)/urdf/links_joints.xacro"/>
    <xacro:include filename="$(find robot_manipulator_5dof)/urdf/robot_parameters.xacro"/>

<!-- *************************************bottom_link**********************************************-->
      <!-- Gripper roll link properties -->
      <property name="gripper_roll_width" value="0.04" />
      <property name="gripper_roll_len" value="0.02" />

      <!-- Left gripper -->
      <property name="left_gripper_len" value="0.02" />
      <property name="left_gripper_width" value="0.02" />
      <property name="left_gripper_height" value="0.08" />

      <!-- Right gripper -->
      <property name="right_gripper_len" value="0.02" />
      <property name="right_gripper_width" value="0.02" />
      <property name="right_gripper_height" value="0.08" />

      <!-- Right gripper -->
      <property name="grasp_frame_len" value="0.02" />
      <property name="grasp_frame_width" value="0.02" />
      <property name="grasp_frame_height" value="0.02" />

    <xacro:macro name="inertial_matrix" params="mass">
        <inertial>
            <mass value="${mass}" />
            <inertia ixx="1.0" ixy="0.0" ixz="0.0" iyy="0.5" iyz="0.0" izz="1.0" />
        </inertial>
    </xacro:macro>

    <!-- *************************************bottom_link********************************************-->
    <link name="dummy_link">
    </link>
    <joint name="dummy_joint" type="fixed">
        <parent link="dummy_link"/>
        <child link="${l000}"/>
    </joint>
    <m_link_cylinder name="${l000}"
        origin_rpy="0 0 0"
        origin_xyz="0 0 0"
        radius="0.08" length="0.03"
        mass= "2000"
        ixx ="0.0" ixy ="0.0" ixz="0.0"
        iyy ="0.0" iyz="0.0"
        izz ="0.0"
        color="black"/>

    <gazebo reference="${l000}">
        <material>Gazebo/Black</material>
    </gazebo>

    <joint name="${l000}__${l00}" type="fixed">
        <axis xyz="0 0 1"/>
        <origin xyz="0 0 0.015" rpy="0 0 0"/>
        <parent link="${l000}"/>
        <child link="${l00}"/>
    </joint>

<!-- *************************************base_link*********************************************-->
    <m_link_cylinder name="${l00}"
        origin_rpy="0 0 0"
        origin_xyz="0 0 0.015"
        length="0.05" radius="0.06"
        mass= "2000"
        ixx ="0.0" ixy ="0.0" ixz="0.0"
        iyy ="0.0" iyz="0.0"
        izz ="0.0"
        color="white"/>

    <gazebo reference="${l00}">
        <material>Gazebo/Black</material>
    </gazebo>

    <m_joint name="${l00}__${l01}"
        type="revolute" axis_xyz="0 0 1"
        limit_e="1000.0" limit_l="0" limit_u="3.14" limit_v="0.5"
        origin_rpy="0 0 0" origin_xyz="0 0 0.028"
        parent="${l00}"
        child="${l01}"/>

<!-- *************************************link_01*********************************************-->
    <m_link_cylinder name="${l01}"
        origin_rpy="0 0 0"
        origin_xyz="0 0 0.02"
        length="0.033" radius="0.03"
        mass= "1"
        ixx ="1.0" ixy ="1.0" ixz="0.0"
        iyy ="0.5" iyz="0.0"
        izz ="1.0"
        color="white"/>

    <gazebo reference="${l01}">
        <material>Gazebo/White</material>
    </gazebo>

  <m_joint name="${l01}__${l02}"
        type="revolute" axis_xyz="0 1 0"
        limit_e="1000.0" limit_l="-3.14" limit_u="3.14" limit_v="0.5"
        origin_rpy="0 0 0" origin_xyz="0 0 0.033"
        parent="${l01}"
        child="${l02}"/>


<!-- *************************************link_02*********************************************-->
    <m_link_cylinder name="${l02}"
        origin_rpy="0 0 0"
        origin_xyz="0 0 0.055"
        length="0.105" radius="0.03"
        mass= "1"
        ixx ="1.0" ixy ="1.0" ixz="0.0"
        iyy ="0.5" iyz="0.0"
        izz ="1.0"
        color="white"/>

    <gazebo reference="${l02}">
        <material>Gazebo/Grey</material>
    </gazebo>

    <m_joint name="${l02}__${l03}"
        type="revolute" axis_xyz="0 1 0"
        limit_e="1000.0" limit_l="0" limit_u="3.14" limit_v="0.5"
        origin_rpy="0 0 0" origin_xyz="0 0 0.105"
        parent="${l02}"
        child="${l03}"/>

<!-- *************************************link_03*********************************************-->
    <m_link_cylinder name="${l03}"
        origin_rpy="0 0 0"
        origin_xyz="0 0 0.052"
        length="0.098" radius="0.03"
        mass= "1"
        ixx ="1.0" ixy ="1.0" ixz="0.0"
        iyy ="0.5" iyz="0.0"
        izz ="1.0"
        color="white"/>

    <gazebo reference="${l03}">
        <material>Gazebo/White</material>
    </gazebo>

    <m_joint name="${l03}__${l04}"
        type="revolute" axis_xyz="0 1 0"
        limit_e="1000.0" limit_l="0" limit_u="3.14" limit_v="0.5"
        origin_rpy="0 0 0" origin_xyz="0 0 0.098"
        parent="${l03}"
        child="${l04}"/>

<!-- *************************************link_04*********************************************-->
    <m_link_cylinder name="${l04}"
        origin_rpy="0 0 0"
        origin_xyz="0 0 0.016"
        length="0.027" radius="0.03"
        mass= "1"
        ixx ="1.0" ixy ="1.0" ixz="0.0"
        iyy ="0.5" iyz="0.0"
        izz ="1.0"
        color="black"/>

    <gazebo reference="${l04}">
        <material>Gazebo/Grey</material>
    </gazebo>

    <m_joint name="${l04}__${l05}"
        type="revolute" axis_xyz="0 0 1"
        limit_e="1000.0" limit_l="0" limit_u="3.14" limit_v="0.5"
        origin_rpy="0 0 0" origin_xyz="0 0 0.027"
        parent="${l04}"
        child="${l05}"/>


<!-- *************************************link_05*********************************************-->
    <m_link_cylinder name="${l05}"
        origin_rpy="0 0 0"
        origin_xyz="0 0 0.035"
        length="0.065" radius="0.03"
        mass= "1"
        ixx ="1.0" ixy ="1.0" ixz="0.0"
        iyy ="0.5" iyz="0.0"
        izz ="1.0"
        color="white"/>

    <gazebo reference="${l05}">
        <material>Gazebo/White</material>
    </gazebo>

    <joint name="finger_joint1" type="prismatic">
        <parent link="${l05}"/>
        <child link="gripper_finger_link1"/>
        <origin xyz="0.0 0 0" />
        <axis xyz="0 1 0" />
        <limit effort="100" lower="0" upper="0.03" velocity="1.0"/>

        <safety_controller k_position="20"
                             k_velocity="20"
                             soft_lower_limit="${-0.15 }"
                             soft_upper_limit="${ 0.0 }"/>
        <dynamics damping="50" friction="1"/>
  </joint>
<!-- *************************************link_05*********************************************-->

<!-- LEFT GRIPPER AFT LINK -->
  <link name="gripper_finger_link1">
     <visual>
      <origin xyz="0.0 -0.02 0.105"/>
      <geometry>
           <box size="${left_gripper_len} ${left_gripper_width} ${left_gripper_height}" />
      </geometry>
      <material name="White" />
    </visual>
    <xacro:inertial_matrix mass="1"/>
  </link>

  <gazebo reference="l_gripper_aft_link">
    <material>Gazebo/White</material>
  </gazebo>

<!-- Joint between Wrist roll and finger 2 -->

  <joint name="finger_joint2" type="prismatic">
    <parent link="${l05}"/>
    <child link="gripper_finger_link2"/>
    <origin xyz="0.0 0.0 0.0" />
    <axis xyz="0 1 0"/>
    <limit effort="1" lower="-0.03" upper="0.0" velocity="1.0"/>

<!--    <mimic joint="gripper_finger_joint" multiplier="-1.0" offset="0.0" /> -->

    <dynamics damping="50" friction="1"/>
  </joint>

<!-- ///////////////////////////////////////////////////////////////////////////////////////////////////////////////////// -->

  <!-- RIGHT GRIPPER AFT LINK -->


  <link name="gripper_finger_link2">
    <visual>
        <origin xyz="0.0 0.02 0.105"/>
        <geometry>
            <box size="${right_gripper_len} ${right_gripper_width} ${right_gripper_height}" />
        </geometry>
        <material name="White"/>
    </visual>
    <xacro:inertial_matrix mass="1"/>
  </link>

  <gazebo reference="r_gripper_aft_link">
    <material>Gazebo/White</material>
  </gazebo>

    <!-- Grasping frame -->
    <link name="grasping_frame">
        <inertial>
            <origin xyz="0 0 0.0" rpy="0 0 0"/>
            <mass value="0.0001"/>
            <cuboid_inertia mass="0.0001" x="0.001" y="0.001" z="0.001"/>
            <inertia  ixx="1.0" ixy="0.0"  ixz="0.0"  iyy="100.0"  iyz="0.0"  izz="1.0" />
        </inertial>
        <visual>
            <origin xyz="0 0 0"/>
            <geometry>
                <box size="${grasp_frame_len} ${grasp_frame_width} ${grasp_frame_height}" />
            </geometry>
            <material name="White"/>
        </visual>
    </link>

    <joint name="grasping_frame_joint" type="fixed">
        <parent link="${l05}"/>
        <child link="grasping_frame"/>
        <origin xyz="0.0 0 0.072" rpy="0 0 0"/>
    </joint>





<!-- *************************************link_01*********************************************-->


<!-- ************************************* ROS control plugin ********************************-->
<!-- To simulate model in order to pasrse the trasnmission tage and assign appropriate hardware interfaces
 and the control manager -->
    <gazebo>
        <plugin name="gazebo_ros_control" filename="libgazebo_ros_control.so">
            <robotNamespace>/joyit</robotNamespace>
            <robotSimType>gazebo_ros_control/DefaultRobotHWSim</robotSimType>
            <legacyModeNS>true</legacyModeNS>
        </plugin>
    </gazebo>

</robot>
